Workbook
Name a: #REF!
Name ACT: #REF!
Name ACT: #REF!
Name AF: #REF!
Name AREA: #REF!
Name AREA: #REF!
Name AS: #REF!
Name BC: '[1]#REF'!#REF!
Name BC: '[1]#REF'!#REF!
Name BQ: #REF!
Name BQ: #REF!
Name CUTOFF: '[2]DDR-MP21'!$BC$6
Name DEPT: #REF!
Name DI: '[1]#REF'!#REF!
Name DI: '[1]#REF'!#REF!
Name DKG: #REF!
Name DKG: #REF!
Name EF: #REF!
Name EF: #REF!
Name EFA: #REF!
Name EFA: #REF!
Name ES: #REF!
Name ES: #REF!
Name ESA: #REF!
Name ESA: #REF!
Name EXCL: #REF!
Name EXCL: #REF!
Name FIL: #REF!
Name FIL: #REF!
Name GRP: #REF!
Name GRP: #REF!
Name GRPG: #REF!
Name KS: #REF!
Name LO: '[1]#REF'!#REF!
Name LO: '[1]#REF'!#REF!
Name MACT: #REF!
Name MACT: #REF!
Name MFIL: #REF!
Name MFIL: #REF!
Name MHR: #REF!
Name MSYS: #REF!
Name MSYS: #REF!
Name MZON: #REF!
Name OD: #REF!
Name OD: #REF!
Name OS: #REF!
Name OSC: #REF!
Name OSC: #REF!
Name ouy: #REF!
Name PCT: #REF!
Name PCT: #REF!
Name PHAS: #REF!
Name PHAS: #REF!
Name PLFN: '[1]#REF'!#REF!
Name PLFN: '[1]#REF'!#REF!
Name PLST: '[1]#REF'!#REF!
Name PLST: '[1]#REF'!#REF!
Name PR: #REF!
Name PR: #REF!
Name RES: #REF!

Sheet Progress Summary
A2: CTR | B2: Category Description | C2: Weightings | D2: Cumulative | H2: This Week % | J2: Overall Variance %
D3: Last Week % | F3: This Week %
D4: Plan | E4: Actual | F4: Plan | G4: Actual | H4: Plan | I4: Actual
A5: ='BACK SUMMARY'!#REF! -> #REF! | B5: ='BACK SUMMARY'!A5 -> #REF! | C5: ='BACK SUMMARY'!B5 -> #REF! | F5: =#REF! -> #REF! | G5: =#REF! -> #REF! | H5: =F5-D5 -> #REF! | I5: =G5-E5 -> #REF! | J5: =G5-F5 -> #REF!
A6: ='BACK SUMMARY'!#REF! -> #REF! | B6: ='BACK SUMMARY'!A6 -> #REF! | C6: ='BACK SUMMARY'!B6 -> #REF! | F6: =#REF! -> #REF! | G6: =#REF! -> #REF! | H6: =F6-D6 -> #REF! | I6: =G6-E6 -> #REF! | J6: =G6-F6 -> #REF!
A7: ='BACK SUMMARY'!#REF! -> #REF! | B7: ='BACK SUMMARY'!A7 -> #REF! | C7: ='BACK SUMMARY'!B7 -> #REF! | F7: =#REF! -> #REF! | G7: =#REF! -> #REF! | H7: =F7-D7 -> #REF! | I7: =G7-E7 -> #REF! | J7: =G7-F7 -> #REF!
A8: ='BACK SUMMARY'!#REF! -> #REF! | B8: ='BACK SUMMARY'!A8 -> #REF! | C8: ='BACK SUMMARY'!B8 -> #REF! | F8: =#REF! -> #REF! | G8: =#REF! -> #REF! | H8: =F8-D8 -> #REF! | I8: =G8-E8 -> #REF! | J8: =G8-F8 -> #REF!
A9: ='BACK SUMMARY'!#REF! -> #REF! | B9: ='BACK SUMMARY'!A9 -> #REF! | C9: ='BACK SUMMARY'!B9 -> #REF! | F9: =#REF! -> #REF! | G9: =#REF! -> #REF! | H9: =F9-D9 -> #REF! | I9: =G9-E9 -> #REF! | J9: =G9-F9 -> #REF!
A10: ='BACK SUMMARY'!#REF! -> #REF! | B10: ='BACK SUMMARY'!A10 -> #REF! | C10: ='BACK SUMMARY'!B10 -> #REF! | F10: =#REF! -> #REF! | G10: =#REF! -> #REF! | H10: =F10-D10 -> #REF! | I10: =G10-E10 -> #REF! | J10: =G10-F10 -> #REF!
A11: ='BACK SUMMARY'!#REF! -> #REF! | B11: ='BACK SUMMARY'!A11 -> #REF! | C11: ='BACK SUMMARY'!B11 -> #REF! | F11: =#REF! -> #REF! | G11: =#REF! -> #REF! | H11: =F11-D11 -> #REF! | I11: =G11-E11 -> #REF! | J11: =G11-F11 -> #REF!
A12: ='BACK SUMMARY'!#REF! -> #REF! | B12: ='BACK SUMMARY'!A12 -> #REF! | C12: ='BACK SUMMARY'!B12 -> #REF! | F12: =#REF! -> #REF! | G12: =#REF! -> #REF! | H12: =F12-D12 -> #REF! | I12: =G12-E12 -> #REF! | J12: =G12-F12 -> #REF!
C13: =SUM(C5:C12) -> #REF! | D13: =SUM(D5:D12) -> 0 | E13: =SUM(E5:E12) -> 0 | F13: =SUM(F5:F12) -> #REF! | G13: =SUM(G5:G12) -> #REF! | H13: =SUM(H5:H12) -> #REF! | I13: =SUM(I5:I12) -> #REF! | J13: =SUM(J5:J12) -> #REF!

Sheet BACK UP S CURVE
D3: 1 | E3: 2 | F3: 3 | G3: 4 | H3: 5 | I3: 6 | J3: 7 | K3: 8 | L3: 9 | M3: 10 | N3: 11 | O3: 12 | P3: 13 | Q3: 14 | R3: 15 | S3: 16 | T3: 17 | U3: 18 | V3: 19 | W3: 20 | X3: 21 | Y3: 22 | Z3: 23 | AA3: 24 | AB3: 25 | AC3: 26 | AD3: 27 | AE3: 28 | AF3: 29 | AG3: 30 | AH3: 31 | AI3: 32 | AJ3: 33 | AK3: 34 | AL3: 35 | AM3: 36 | AN3: 37 | AO3: 38 | AP3: 39 | AQ3: 40 | AR3: 41 | AS3: 42 | AT3: 43 | AU3: 44 | AV3: 45 | AW3: 46 | AX3: 47 | AY3: 48 | AZ3: 49 | BA3: 50 | BB3: 51 | BC3: 52 | BD3: 53 | BE3: 54 | BF3: 55
D4: 41325 | E4: =+D4+7 -> 41332 | F4: =+E4+7 -> 41339 | G4: =+F4+7 -> 41346 | H4: =+G4+7 -> 41353 | I4: =+H4+7 -> 41360 | J4: =+I4+7 -> 41367 | K4: =+J4+7 -> 41374 | L4: =+K4+7 -> 41381 | ... BK4: =+BJ4+7 -> 41738
A5: ='BACK SUMMARY'!A5 -> #REF! | B5: ='BACK SUMMARY'!B5 -> #REF! | C5: ='BACK SUMMARY'!C5 -> #REF! | D5: =SUM(#REF!) -> #REF! | E5: =SUM(#REF!) -> #REF! | F5: =SUM(#REF!) -> #REF! | G5: =SUM(#REF!) -> #REF! | H5: =SUM(#REF!) -> #REF! | I5: =SUM(#REF!) -> #REF! | J5: =SUM(#REF!) -> #REF! | K5: =SUM(#REF!) -> #REF! | ... BK5: =SUM(#REF!) -> #REF!
A6: ='BACK SUMMARY'!A6 -> #REF! | B6: ='BACK SUMMARY'!B6 -> #REF! | C6: ='BACK SUMMARY'!C6 -> #REF! | D6: =SUM(#REF!) -> #REF! | E6: =SUM(#REF!) -> #REF! | F6: =SUM(#REF!) -> #REF! | G6: =SUM(#REF!) -> #REF! | H6: =SUM(#REF!) -> #REF! | I6: =SUM(#REF!) -> #REF! | J6: =SUM(#REF!) -> #REF! | K6: =SUM(#REF!) -> #REF! | ... BK6: =SUM(#REF!) -> #REF!
A7: ='BACK SUMMARY'!A7 -> #REF! | B7: ='BACK SUMMARY'!B7 -> #REF! | C7: ='BACK SUMMARY'!C7 -> #REF! | D7: =SUM(#REF!) -> #REF! | E7: =SUM(#REF!) -> #REF! | F7: =SUM(#REF!) -> #REF! | G7: =SUM(#REF!) -> #REF! | H7: =SUM(#REF!) -> #REF! | I7: =SUM(#REF!) -> #REF! | J7: =SUM(#REF!) -> #REF! | K7: =SUM(#REF!) -> #REF! | ... BK7: =SUM(#REF!) -> #REF!
A8: ='BACK SUMMARY'!A8 -> #REF! | B8: ='BACK SUMMARY'!B8 -> #REF! | C8: ='BACK SUMMARY'!C8 -> #REF! | D8: =SUM(#REF!) -> #REF! | E8: =SUM(#REF!) -> #REF! | F8: =SUM(#REF!) -> #REF! | G8: =SUM(#REF!) -> #REF! | H8: =SUM(#REF!) -> #REF! | I8: =SUM(#REF!) -> #REF! | J8: =SUM(#REF!) -> #REF! | K8: =SUM(#REF!) -> #REF! | ... BK8: =SUM(#REF!) -> #REF!
A9: ='BACK SUMMARY'!A9 -> #REF! | B9: ='BACK SUMMARY'!B9 -> #REF! | C9: ='BACK SUMMARY'!C9 -> #REF! | D9: =SUM(#REF!) -> #REF! | E9: =SUM(#REF!) -> #REF! | F9: =SUM(#REF!) -> #REF! | G9: =SUM(#REF!) -> #REF! | H9: =SUM(#REF!) -> #REF! | I9: =SUM(#REF!) -> #REF! | J9: =SUM(#REF!) -> #REF! | K9: =SUM(#REF!) -> #REF! | ... BK9: =SUM(#REF!) -> #REF!
A10: ='BACK SUMMARY'!A10 -> #REF! | B10: ='BACK SUMMARY'!B10 -> #REF! | C10: ='BACK SUMMARY'!C10 -> #REF! | D10: =SUM(#REF!) -> #REF! | E10: =SUM(#REF!) -> #REF! | F10: =SUM(#REF!) -> #REF! | G10: =SUM(#REF!) -> #REF! | H10: =SUM(#REF!) -> #REF! | I10: =SUM(#REF!) -> #REF! | J10: =SUM(#REF!) -> #REF! | K10: =SUM(#REF!) -> #REF! | ... BK10: =SUM(#REF!) -> #REF!
A11: ='BACK SUMMARY'!A11 -> #REF! | B11: ='BACK SUMMARY'!B11 -> #REF! | C11: ='BACK SUMMARY'!C11 -> #REF! | D11: =SUM(#REF!) -> #REF! | E11: =SUM(#REF!) -> #REF! | F11: =SUM(#REF!) -> #REF! | G11: =SUM(#REF!) -> #REF! | H11: =SUM(#REF!) -> #REF! | I11: =SUM(#REF!) -> #REF! | J11: =SUM(#REF!) -> #REF! | K11: =SUM(#REF!) -> #REF! | ... BK11: =SUM(#REF!) -> #REF!
A12: ='BACK SUMMARY'!A12 -> #REF! | B12: ='BACK SUMMARY'!B12 -> #REF! | C12: ='BACK SUMMARY'!C12 -> #REF! | D12: =SUM(#REF!) -> #REF! | E12: =SUM(#REF!) -> #REF! | F12: =SUM(#REF!) -> #REF! | G12: =SUM(#REF!) -> #REF! | H12: =SUM(#REF!) -> #REF! | I12: =SUM(#REF!) -> #REF! | J12: =SUM(#REF!) -> #REF! | K12: =SUM(#REF!) -> #REF! | ... BK12: =SUM(#REF!) -> #REF!
B13: =SUM(B5:B12) -> #REF! | C13: =SUM(C5:C12) -> #REF! | D13: =SUM(D5:D12) -> #REF! | E13: =SUM(E5:E12) -> #REF! | F13: =SUM(F5:F12) -> #REF! | G13: =SUM(G5:G12) -> #REF! | H13: =SUM(H5:H12) -> #REF! | I13: =SUM(I5:I12) -> #REF! | ... BK13: =SUM(BK5:BK12) -> #REF!
D16: 1 | E16: 2 | F16: 3 | G16: 4 | H16: 5 | I16: 6 | J16: 7 | K16: 8 | L16: 9 | M16: 10 | N16: 11 | O16: 12 | P16: 13 | Q16: 14 | R16: 15 | S16: 16 | T16: 17 | U16: 18 | V16: 19 | W16: 20 | X16: 21 | Y16: 22 | Z16: 23 | AA16: 24 | AB16: 25 | AC16: 26 | AD16: 27 | AE16: 28 | AF16: 29 | AG16: 30 | AH16: 31 | AI16: 32 | AJ16: 33 | AK16: 34 | AL16: 35 | AM16: 36 | AN16: 37 | AO16: 38 | AP16: 39 | AQ16: 40 | AR16: 41 | AS16: 42 | AT16: 43 | AU16: 44 | AV16: 45 | AW16: 46 | AX16: 47 | AY16: 48 | AZ16: 49 | BA16: 50 | BB16: 51 | BC16: 52 | BD16: 53 | BE16: 54 | BF16: 55
D17: 40780 | E17: =+D17+7 -> 40787 | F17: =+E17+7 -> 40794 | G17: =+F17+7 -> 40801 | H17: =+G17+7 -> 40808 | I17: =+H17+7 -> 40815 | J17: =+I17+7 -> 40822 | K17: =+J17+7 -> 40829 | L17: =+K17+7 -> 40836 | ... BK17: =+BJ17+7 -> 41193
A18: ='BACK SUMMARY'!A5 -> #REF! | B18: ='BACK SUMMARY'!B5 -> #REF! | C18: ='BACK SUMMARY'!C5 -> #REF!
A19: ='BACK SUMMARY'!A6 -> #REF! | B19: ='BACK SUMMARY'!B6 -> #REF! | C19: ='BACK SUMMARY'!C6 -> #REF!
A20: ='BACK SUMMARY'!A7 -> #REF! | B20: ='BACK SUMMARY'!B7 -> #REF! | C20: ='BACK SUMMARY'!C7 -> #REF!
A21: ='BACK SUMMARY'!A8 -> #REF! | B21: ='BACK SUMMARY'!B8 -> #REF! | C21: ='BACK SUMMARY'!C8 -> #REF!
A22: ='BACK SUMMARY'!A9 -> #REF! | B22: ='BACK SUMMARY'!B9 -> #REF! | C22: ='BACK SUMMARY'!C9 -> #REF!
A23: ='BACK SUMMARY'!A10 -> #REF! | B23: ='BACK SUMMARY'!B10 -> #REF! | C23: ='BACK SUMMARY'!C10 -> #REF!
A24: ='BACK SUMMARY'!A11 -> #REF! | B24: ='BACK SUMMARY'!B11 -> #REF! | C24: ='BACK SUMMARY'!C11 -> #REF!
A25: ='BACK SUMMARY'!A12 -> #REF! | B25: ='BACK SUMMARY'!B12 -> #REF! | C25: ='BACK SUMMARY'!C12 -> #REF!
B26: =SUM(B18:B25) -> #REF! | C26: =SUM(C18:C25) -> #REF! | D26: =SUM(D18:D25) -> 0 | E26: =SUM(E18:E25) -> 0 | F26: =SUM(F18:F25) -> 0 | G26: =SUM(G18:G25) -> 0 | H26: =SUM(H18:H25) -> 0 | I26: =SUM(I18:I25) -> 0 | ... BK26: =SUM(BK18:BK25) -> 0
C28: Plan - Weekly | D28: =+D29 -> #REF! | E28: =+E29-D29 -> #REF! | F28: =+F29-E29 -> #REF! | G28: =+G29-F29 -> #REF! | H28: =+H29-G29 -> #REF! | I28: =+I29-H29 -> #REF! | J28: =+J29-I29 -> #REF! | K28: =+K29-J29 -> #REF! | L28: =+L29-K29 -> #REF! | ... BK28: =+BK29-BJ29 -> #REF!
C29: Plan - Cumulative | D29: =D13 -> #REF! | E29: =E13 -> #REF! | F29: =F13 -> #REF! | G29: =G13 -> #REF! | H29: =H13 -> #REF! | I29: =I13 -> #REF! | J29: =J13 -> #REF! | K29: =K13 -> #REF! | ... BK29: =BK13 -> #REF!
C31: Actual - Weekly | D31: =D26 -> 0 | E31: =E32-D32 -> 0 | F31: =F32-E32 -> 0 | G31: =G32-F32 -> 0 | H31: =H32-G32 -> 0 | I31: =I32-H32 -> 0 | J31: =J32-I32 -> 0
C32: Actual - Cumulative
C34: Frecast Weekly -
C36: Forecast - Cumulative
C40: Forecast | D40: =+E4 -> 41332 | E40: =+I4 -> 41360 | F40: =+M4 -> 41388 | G40: =+R4 -> 41423 | H40: =+V4 -> 41451 | I40: =+AA4 -> 41486 | J40: =+AE4 -> 41514 | K40: =+AI4 -> 41542 | L40: =+AN4 -> 41577 | M40: =+AR4 -> 41605 | N40: =+AV4 -> 41633
D41: =+E13 -> #REF! | E41: =+I13*100 -> #REF! | F41: =+M13*100 -> #REF! | G41: =+R13*100 -> #REF! | H41: =+V13*100 -> #REF! | I41: =+AA13*100 -> #REF! | J41: =+AE13*100 -> #REF! | K41: =+AI13*100 -> #REF! | L41: =+AN13*100 -> #REF! | M41: =+AR13*100 -> #REF! | N41: =+AV13*100 -> #REF!
AA42: 0.89502488
D43: =+D41 -> #REF! | E43: =+E41-D41 -> #REF! | F43: =+F41-E41 -> #REF! | G43: =+G41-F41 -> #REF! | H43: =+H41-G41 -> #REF! | I43: =+I41-H41 -> #REF! | J43: =+J41-I41 -> #REF! | K43: =+K41-J41 -> #REF! | L43: =+L41-K41 -> #REF! | ... N43: =+N41-M41 -> #REF!
D48: 0 | E48: 1 | F48: 3 | G48: 1 | H48: 2 | I48: 2 | J48: 5 | K48: 11 | L48: 18 | M48: 16 | N48: 17
D49: =D51/45 -> #REF! | E49: =E51/45 -> #REF! | F49: =F51/45 -> #REF! | G49: =G51/45 -> #REF! | H49: =H51/45 -> #REF! | I49: =I51/45 -> #REF! | J49: =J51/45 -> #REF! | K49: =K51/45 -> #REF! | ... BF49: =BF51/45 -> #REF!
C51: Manhours Planned | D51: =D28*#REF! -> #REF! | E51: =E28*#REF! -> #REF! | F51: =F28*#REF! -> #REF! | G51: =G28*#REF! -> #REF! | H51: =H28*#REF! -> #REF! | I51: =I28*#REF! -> #REF! | J51: =J28*#REF! -> #REF! | K51: =K28*#REF! -> #REF! | ... BF51: =BF28*#REF! -> #REF!
C52: Forecast Manhours | R52: =R34*#REF! -> #REF! | S52: =S34*#REF! -> #REF! | T52: =T34*#REF! -> #REF! | U52: =U34*#REF! -> #REF! | V52: =V34*#REF! -> #REF! | W52: =W34*#REF! -> #REF! | X52: =X34*#REF! -> #REF! | Y52: =Y34*#REF! -> #REF! | ... BF52: =BF34*#REF! -> #REF!
C53: Actual Manhours | D53: =D30*#REF! -> #REF! | E53: 182 | F53: 181 | G53: 176 | H53: 256.5 | I53: 410 | J53: 368 | K53: 486 | L53: 597 | M53: 662 | N53: 492 | O53: 615.5 | P53: 588 | Q53: 108
F69: 0 | G69: 0.017 | H69: 0.026 | I69: 0.037

Sheet OVERALL-S-CURVE
B2: OVERALL PROGRESS 'S' CURVE | AP2: =CONCATENATE("Date",": ",TEXT(#REF!,"DD-MMM-YY")) -> #REF!
B3: EPC WORKS FOR PROVISION OF NEW 24” LEAN GAS PIPELINE FROM BUHASA TO BAB & BAB TO THAMMAMA
C53: Date / week | D53: =+'BACK UP S CURVE'!E4 -> 41332 | E53: =+'BACK UP S CURVE'!F4 -> 41339 | F53: =+'BACK UP S CURVE'!G4 -> 41346 | G53: =+'BACK UP S CURVE'!H4 -> 41353 | H53: =+'BACK UP S CURVE'!I4 -> 41360 | I53: =+'BACK UP S CURVE'!J4 -> 41367 | J53: =+'BACK UP S CURVE'!K4 -> 41374 | K53: =+'BACK UP S CURVE'!L4 -> 41381 | ... AQ53: =+'BACK UP S CURVE'!AR4 -> 41605
C54: Over All Plan % Per Month | D54: =+'BACK UP S CURVE'!E29 -> #REF! | E54: =+E55-D55 -> #REF! | F54: =+F55-E55 -> #REF! | G54: =+G55-F55 -> #REF! | H54: =+H55-G55 -> #REF! | I54: =+I55-H55 -> #REF! | J54: =+J55-I55 -> #REF! | K54: =+K55-J55 -> #REF! | L54: =+L55-K55 -> #REF! | ... AQ54: =+AQ55-AP55 -> #REF!
C55: Commulative Overall % per Month | D55: =+'BACK UP S CURVE'!E29 -> #REF! | E55: =+'BACK UP S CURVE'!F29 -> #REF! | F55: =+'BACK UP S CURVE'!G29 -> #REF! | G55: =+'BACK UP S CURVE'!H29 -> #REF! | H55: =+'BACK UP S CURVE'!I29 -> #REF! | I55: =+'BACK UP S CURVE'!J29 -> #REF! | J55: =+'BACK UP S CURVE'!K29 -> #REF! | K55: =+'BACK UP S CURVE'!L29 -> #REF! | ... AQ55: =+'BACK UP S CURVE'!AR29 -> #REF!
B63: WBS | C63: DESCRIPTION

Sheet BACK SUMMARY
A3: Category Description | B3: Weighting (%) | D3: % Progress
D4: PLAN | E4: FORECAST | F4: ACTUAL
A5: =#REF! -> #REF! | B5: =SUM(#REF!) -> #REF! | C5: =B5/$B$13/100 -> #REF! | D5: =SUM(#REF!) -> #REF! | F5: =SUM(#REF!) -> #REF!
A6: =#REF! -> #REF! | B6: =SUM(#REF!) -> #REF! | C6: =B6/$B$13/100 -> #REF! | D6: =SUM(#REF!) -> #REF! | F6: =SUM(#REF!) -> #REF!
A7: =#REF! -> #REF! | B7: =SUM(#REF!) -> #REF! | C7: =B7/$B$13/100 -> #REF! | D7: =SUM(#REF!) -> #REF! | F7: =SUM(#REF!) -> #REF!
A8: =#REF! -> #REF! | B8: =SUM(#REF!) -> #REF! | C8: =B8/$B$13/100 -> #REF! | D8: =SUM(#REF!) -> #REF! | F8: =SUM(#REF!) -> #REF!
A9: =#REF! -> #REF! | B9: =SUM(#REF!) -> #REF! | C9: =B9/$B$13/100 -> #REF! | D9: =SUM(#REF!) -> #REF! | F9: =SUM(#REF!) -> #REF!
A10: =#REF! -> #REF! | B10: =SUM(#REF!) -> #REF! | C10: =B10/$B$13/100 -> #REF! | D10: =SUM(#REF!) -> #REF! | F10: =SUM(#REF!) -> #REF!
A11: =#REF! -> #REF! | B11: =SUM(#REF!) -> #REF! | C11: =B11/$B$13/100 -> #REF! | D11: =SUM(#REF!) -> #REF! | F11: =SUM(#REF!) -> #REF!
A12: =#REF! -> #REF! | B12: =SUM(#REF!) -> #REF! | C12: =B12/$B$13/100 -> #REF! | D12: =SUM(#REF!) -> #REF! | F12: =SUM(#REF!) -> #REF!
A13: TOTAL | B13: =SUM(B5:B12)/100 -> #REF! | C13: =SUM(C5:C12) -> #REF! | D13: =SUM(D5:D12) -> #REF! | F13: =SUM(F5:F12) -> #REF!
E14: =+D13-E13 -> #REF!

Sheet Sheet1
A1: RTU I/O SUMMARY
A2: BUHASA
A3: S. No. | B3: Number of AI | C3: Number of DI | D3: Number of DO | E3: Number of AO
A4: 1 | B4: 402-PIT-201 | C4: 402-RZSO-201A | D4: 402-RSOV-201A
A5: 2 | B5: 402-PIT-202 | C5: 402-RZSO-201B | D5: 402-RSOV-201B
A6: 3 | B6: 402-TIT-201 | C6: 402-RZSC-201
A7: 4 | B7: 402-ZS-201 | C7: 402-MZSO-202
A8: 5 | B8: 402-ZS-202 | C8: 402-MZSC-202
A9: 6 | B9: 402-ET-207 | C9: 402-MXS-202
A10: 7 | B10: 402-IT-206 | C10: 402-MZSO-203
A11: 8 | B11: 402-ET-209 | C11: 402-MZSC-203
A12: 9 | B12: 402-ET-210 | C12: 402-MXS-203
A13: 10 | C13: 402-ET-201
A14: 11 | C14: 402-ET-202
A15: 12 | C15: 402-ET-203
A16: 13 | C16: 402-ET-204
A17: 14 | C17: 402-XS-205
A18: 15 | C18: 402-ET-206
A19: 16 | C19: 402-XS-211
A20: 17 | C20: 402-XS-212
A21: 18 | C21: 402-XS-213
A22: 19 | C22: 402-ZL-201
A23: 20 | C23: 402-ZL-202
A24: 21 | C24: 402-ESL-105 | F24: EXISTING
A25: 22 | C25: 402-ESL-104 | F25: EXISTING
A27: SECTIONALIZING VALVE STATION (SV-1)
A28: S. No. | B28: Number of AI | C28: Number of DI | D28: Number of DO | E28: Number of AO
A29: 1 | B29: 584-PIT-111 | C29: 584-RZSO-101A | D29: 584-RSOV-101A | E29: 584-PIC-211A
A30: 2 | B30: 584-PDIT-114 | C30: 584-RZSO-101B | D30: 584-RSOV-101B | E30: 584-PIC-211B
A31: 3 | B31: 584-TIT-111 | C31: 584-RZSC-101 | D31: 505-HSC-3100
A32: 4 | B32: 584-ZS-112 | C32: 584-XS-101 | D32: 505-HSO-3100
A33: 5 | B33: 584-IT-116A | C33: 584-XS-102 | D33: 505-SOV-701A
A34: 6 | B34: 584-IT-116B | C34: 584-TSH-103 | D34: 505-SOV-701B
A35: 7 | B35: 505-FI-3100-01 | C35: 584-XS-104 | D35: 584-SOV-211B
A36: 8 | B36: 505-PI-3100-01 | C36: 584-ESH-110A
A37: 9 | B37: 505-TI-3100-01 | C37: 584-ESH-111A
A38: 10 | B38: 505-PI-3100-04 | C38: 584-ESL-112A
A39: 11 | B39: 505-PIT-704 | C39: 584-ESL-113A
A40: 12 | B40: 505-PIT-705 | C40: 584-XS-114
A41: 13 | B41: 505-PIT-3100-02 | C41: 584-XS-115A
...
